Workbook

Sheet INV CARNES
B1: CONTEO MIRCOLES 3 DE JULIO A LAS 8AM
B2: FECHA:
B3: INVENTARIO INICIAL | C3: PORCIONES | D3: TIPO DE CARNE | E3: LOMO SALTADO | F3: LOMITO | G3: FILET DE POLLO | H3: HAMBURGUESA | I3: ROYAL | L3: TIPO DE CARNE | M3: LOMO SALTADO | N3: LOMITO | O3: FILET DE POLLO | P3: HAMBURGUESA | Q3: ROYAL | R3: COTOLETA
B4: LOMO SALTADO | C4: 17 | D4: FICHA DE INGRESO
B5: LOMITO | C5: 6 | L5: PROVEEDOR 1
B6: FILET DE POLLO | C6: 49 | L6: PROVEDOR 2
B7: HAMBURGUESA | C7: 19 | D7: FECHA | E7: 45512 | F7: 45512 | L7: FECHA
B8: HAMBURGUESA NIÑOS | D8: KILOS | L8: KILOS
B9: RIB EYE | C9: 13 | D9: MERMA EN GRAMOS | L9: MERMA EN GRAMOS
B10: DALMONICO | D10: FILET/PORCIONES | E10: 1 | F10: 9 | L10: FILET/PORCIONES
B11: CHURRASCO | D11: VENTA LUNES | E11: 2
B12: TOMAHAK | C12: 3 | D12: VENTA MARTES
B13: TACOS CARNE | D13: VENTA MIERCOLES
D14: VENTA JUEVES
D15: VENTA VIERNES
D16: VENTA SABADO
D17: VENTA DOMINGO
D18: VENTAS TOTALES | E18: =SUM(E11:E17) -> 2 | F18: =SUM(F11:F17) -> 0 | G18: =SUM(G11:G17) -> 0 | H18: =SUM(H11:H17) -> 0 | I18: =SUM(I11:I17) -> 0 | J18: =SUM(J11:J17) -> 0
K20: PRODUCTO | L20: TOTAL MERMA EN GRAMOS
B21: INVENTARIO TOTAL | C21: INVENTARIO TOTAL | D21: VENTAS TOTALES | E21: BALANCE | F21: CONTEO | G21: DIFERENCIA | K21: LOMO SALTADO | L21: =E9+M9 -> 0
B22: LOMO SALTADO | C22: =C4+E10+M10 -> 18 | D22: ='CONTEO CARNES'!N27 -> 22 | E22: =C22-D22 -> -4 | G22: =F22-E22 -> 4 | K22: LOMITO | L22: =F9+N9 -> 0
B23: LOMITO | C23: =C5+F10+N10 -> 15 | D23: ='CONTEO CARNES'!M27 -> 16 | E23: =C23-D23 -> -1 | G23: =F23-E23 -> 1 | K23: FILET DE POLLO | L23: =G9+O9 -> 0
B24: FILET DE POLLO | C24: =C6+G10+O10 -> 49 | D24: ='CONTEO CARNES'!K27 -> 36 | E24: =C24-D24 -> 13 | G24: =F24-E24 -> -13 | K24: HAMBURGUESA | L24: =H9+P9 -> 0
B25: HAMBURGUESA | C25: =C7+H10+P10 -> 19 | D25: ='CONTEO CARNES'!L27 -> 13 | E25: =C25-D25 -> 6 | G25: =F25-E25 -> -6 | K25: ROYAL | L25: =I9+Q9 -> 0
B26: ROYAL | C26: =C8+I10+Q10 -> 0 | D26: ='CONTEO CARNES'!O27 -> 10 | E26: =C26-D26 -> -10 | G26: =F26-E26 -> 10 | K26: COTOLETA
D27: =J18 -> 0 | E27: =C27-D27 -> 0 | G27: =F27-E27 -> 0

Sheet INV MARISCOS
B1: CONTEO MIRCOLES 7 DE AGOSTO 8AM
B2: FECHA:
B3: INVENTARIO INICIAL | C3: PORCIONES | D3: TIPO DE CARNE | E3: DORADO | F3: MARLIN | G3: ATUN | H3: CAMARONES | I3: CALAMARES | J3: SALMON TARTAR | K3: CAMARON JUMBO | L3: CAMARON JUVENIL | N3: TIPO DE CARNE | O3: DORADO | P3: MARLIN | Q3: ATUN | R3: CAMARONES | S3: CALAMARES | T3: SALMON TARTAR | U3: CAMARON JUMBO | V3: CAMARON JUVENIL
B4: FILET PESCADO | C4: 29 | D4: FICHA DE INGRESO
B6: MARLIN | C6: 39 | N6: PROVEEDOR 1
B7: ATUN | C7: 21 | N7: PROVEDOR 2
B8: CAMARONES | C8: 83 | D8: FECHA | E8: 45511 | N8: FECHA
B9: CALAMARES | C9: 41 | D9: KILOS | N9: KILOS
B10: SALMON TARTAR | C10: 16 | D10: MERMA EN GRAMOS | F10: 0 | G10: 0 | H10: 0 | I10: 0 | J10: 0 | K10: 0 | N10: MERMA EN GRAMOS | O10: 0 | P10: 0 | Q10: 0 | R10: 0 | S10: 0 | T10: 0 | U10: 0
B11: CAMARONES JUMBO | D11: FILET/PORCIONES | E11: 31 | N11: FILET/PORCIONES
B12: CAMARONES JUVENILES | C12: 17 | D12: VENTA LUNES
B13: DEDOS PESCADO | C13: 8 | D13: VENTA MARTES
B14: CHICHARRON PESCADO | D14: VENTA MIERCOLES
B15: TARTAR | C15: 14 | D15: VENTA JUEVES
D16: VENTA VIERNES
D17: VENTA SABADO
D18: VENTA DOMINGO
D19: VENTAS TOTALES | E19: =SUM(E12:E18) -> 0 | F19: =SUM(F12:F18) -> 0 | G19: =SUM(G12:G18) -> 0 | H19: =SUM(H12:H18) -> 0 | I19: =SUM(I12:I18) -> 0 | J19: =SUM(J12:J18) -> 0 | K19: =SUM(K12:K18) -> 0
M21: PRODUCTO | N21: TOTAL MERMA EN GRAMOS
B22: INVENTARIO TOTAL | C22: INVENTARIO TOTAL | D22: VENTAS TOTALES | E22: BALANCE | F22: CONTEO | G22: DIFERENCIA | M22: DORADO | N22: =E10+O10 -> 0
B23: DORADO | C23: =C4+E11 -> 60 | D23: ='CONTEO MARISCOS'!L43 -> 0 | E23: =C23-D23 -> 60 | G23: =F23-E23 -> -60 | M23: MARLIN | N23: =F10+P10 -> 0
B24: MARLIN | C24: =C6+F11 -> 39 | D24: ='CONTEO MARISCOS'!K43 -> 1 | E24: =C24-D24 -> 38 | G24: =F24-E24 -> -38 | M24: ARUN | N24: =G10+Q10 -> 0
B25: ATUN | C25: =C7+G11 -> 21 | D25: ='CONTEO MARISCOS'!M43 -> 0 | E25: =C25-D25 -> 21 | G25: =F25-E25 -> -21 | M25: CAMARONES | N25: =H10+R10 -> 0
B26: CAMARONES | C26: =C8+H11 -> 83 | D26: ='CONTEO MARISCOS'!N43 -> 1 | E26: =C26-D26 -> 82 | G26: =F26-E26 -> -82 | M26: CALAMARES | N26: =I10+S10 -> 0
B27: CALAMARES | C27: =C9+I11 -> 41 | D27: ='CONTEO MARISCOS'!O43 -> 1 | E27: =C27-D27 -> 40 | G27: =F27-E27 -> -40 | M27: SALMON TARTAR | N27: =J10+T10 -> 0
B28: SALMON TARTAR | C28: =C10+J11 -> 16 | D28: ='CONTEO MARISCOS'!T43 -> 0 | E28: =C28-D28 -> 16 | G28: =F28-E28 -> -16 | M28: CAMARON JUMBO
B29: CAMARON JUMBO | C29: =C11+K11 -> 0 | D29: ='CONTEO MARISCOS'!P43 -> 0 | E29: =C29-D29 -> 0 | G29: =F29-E29 -> 0
B30: CAMARON JUVENIL | C30: =C12+L11 -> 17 | D30: ='CONTEO MARISCOS'!U43 -> 0 | E30: =C30-D30 -> 17 | G30: =F30-E30 -> -17

Sheet CONTEO MARISCOS
B2: LUNES | C2: MARTES | D2: MIÉRCOLES | E2: JUEVES | F2: VIERNES | G2: SÁBADO | H2: DOMINGO | I2: CANTIDAD DE PLATOS | J2: NOMBRE DEL PLATILLO | K2: MARLIN | L2: DORADO | M2: ATUN | N2: CAMARONES | O2: CALAMARES | P2: CAMARON JUMBO | Q2: JUMBO NARANJA | R2: LANGOSTA | S2: PULPO | T2: SALMON | U2: CAMARONES JUVENILES
I3: =SUM(B3:H3) -> 0 | J3: TIRADITO CLASICO | K3: =1*I3 -> 0
I4: =SUM(B4:H4) -> 0 | J4: TIRADITO APALTADO | K4: =I4*1 -> 0
I5: =SUM(B5:H5) -> 0 | J5: TIADITO ESPECIAL | K5: =I5*1 -> 0 | N5: =I5*1 -> 0
I6: =SUM(B6:H6) -> 0 | J6: TIRADITO EN SALSA DE AJI | K6: =I6*1 -> 0
I7: =SUM(B7:H7) -> 0 | J7: TUNA TARTARE | M7: =I7*1 -> 0
I8: =SUM(B8:H8) -> 0 | J8: CHICHARRON DE CALAMAR | O8: =I8*2 -> 0
I9: =SUM(B9:H9) -> 0 | J9: CEVICHE DE PESCADO | K9: =I9*1 -> 0
I10: =SUM(B10:H10) -> 0 | J10: CEVICHE MIXTO | K10: =I10*1 -> 0 | N10: =I10*1 -> 0 | O10: =I10*1 -> 0
H11: 1 | I11: =SUM(B11:H11) -> 1 | J11: CEVICHE CPN | K11: =I11*1 -> 1 | N11: =I11*1 -> 1 | O11: =I11*1 -> 1
I12: =SUM(B12:H12) -> 0 | J12: TARTAR DE SALMON | T12: =I12*1 -> 0
I13: =SUM(B13:H13) -> 0 | J13: CAMARONES JUMBO | P13: =I13*1 -> 0
I14: =SUM(B14:H14) -> 0 | J14: COCTEL DE CAMARONES | N14: =I14*2 -> 0
I15: =SUM(B15:H15) -> 0 | J15: CAUSA DE CAMARONES | N15: =I15*1 -> 0
I16: =SUM(B16:H16) -> 0 | J16: TUNA TERIYAKI | M16: =I16*1 -> 0
I17: =SUM(B17:H17) -> 0 | J17: ARROZ CON CAMARONES | N17: =I17*2 -> 0
I18: =SUM(B18:H18) -> 0 | J18: ARROZ CON MARISCOS | L18: =I18*1 -> 0 | N18: =I18*1 -> 0 | O18: =I18*1 -> 0
I19: =SUM(B19:H19) -> 0 | J19: FETTUCCINI CON CAMARONES | N19: =I19*2 -> 0
I20: =SUM(B20:H20) -> 0 | J20: PARIHUELA DE MARISCOS | L20: =I20*1 -> 0 | N20: =I20*1 -> 0 | O20: =I20*1 -> 0
I21: =SUM(B21:H21) -> 0 | J21: CASADO DE PESCADO | L21: =I21*1 -> 0
I22: =SUM(B22:H22) -> 0 | J22: CHORRILLANA | L22: =I22*1 -> 0
I23: =SUM(B23:H23) -> 0 | J23: CHICHARRON DE PESCADO | L23: =I23*2 -> 0
I24: =SUM(B24:H24) -> 0 | J24: CHICHARRON MIXTO | L24: =I24*1 -> 0 | N24: =I24*1 -> 0 | O24: =I24*1 -> 0
I25: =SUM(B25:H25) -> 0 | J25: PESCADO A LO MACHO | L25: =I25*1 -> 0 | N25: =I25*1 -> 0 | O25: =I25*1 -> 0
I26: =SUM(B26:H26) -> 0 | J26: ALCAPARRAS | L26: =I26*1 -> 0
I27: =SUM(B27:H27) -> 0 | J27: DORADO MARACUYA | L27: =I27*1 -> 0
I28: 0 | J28: DORADO A LA NARANJA | L28: =I28*1 -> 0 | Q28: =I28*1 -> 0 | U28: =I28*1 -> 0
I29: =SUM(B29:H29) -> 0 | J29: SURF TACOS DE PESCADO | L29: =I29*1 -> 0
I30: =SUM(B30:H30) -> 0 | J30: SURF TACOS DE CAMARONES | N30: =I30*2 -> 0
I31: =SUM(B31:H31) -> 0 | J31: CPN BURRITOS PESCADO | L31: =I31*1 -> 0
I32: =SUM(B32:H32) -> 0 | J32: CPN BURRITOS CAMARON | N32: =I32*2 -> 0
I33: =SUM(B33:H33) -> 0 | J33: DEDOS DE PESCADO CON PAPAS | L33: =I33*1 -> 0
I34: =SUM(B34:H34) -> 0 | J34: ORDEN DE CAMARONES | N34: =I34*2 -> 0
I35: =SUM(B35:H35) -> 0 | J35: FILET DE DORADO | L35: =I35*1 -> 0
I36: =SUM(B36:H36) -> 0 | J36: FILET DE ATUN | M36: =I36*1 -> 0
I37: =SUM(B37:H37) -> 0 | J37: PARGO
I38: =SUM(B38:H38) -> 0 | J38: SUSHI ATUNY CAMARONES | N38: =I38*1 -> 0
I39: =SUM(B39:H39) -> 0 | J39: SUSHI SALMON
I40: =SUM(B40:H40) -> 0 | J40: SUSHI DE ATUN | M40: =I40*1 -> 0
I41: =SUM(B41:H41) -> 0
...

Sheet CONTEO CARNES
B2: LUNES | C2: MARTES | D2: MIÉRCOLES | E2: JUEVES | F2: VIERNES | G2: SÁBADO | H2: DOMINGO | I2: CANTIDAD DE PLATOS | J2: NOMBRE DEL PLATILLO | K2: FILET DE POLLO | L2: HAMBURGUESA | M2: LOMITO | N2: LOMO SALTADO | O2: ROYAL | P2: RIB EYE
H3: 7 | I3: =SUM(B3:H3) -> 7 | J3: CASADO DE POLLO | K3: =I3*1 -> 7
H4: 4 | I4: =SUM(B4:H4) -> 4 | J4: CHAMPIGNON DE POLLO | K4: =I4*1 -> 4
H5: 7 | I5: =SUM(B5:H5) -> 7 | J5: POLLO SALTADO | K5: =I5*1 -> 7
I6: =SUM(B6:H6) -> 0 | J6: FETTUCCINI BOLOGNESA
H7: 7 | I7: =SUM(B7:H7) -> 7 | J7: CHAMPIGNON DE LOMO | M7: =I7*1 -> 7
H8: 22 | I8: =SUM(B8:H8) -> 22 | J8: LOMO SALTADO | N8: =I8*1 -> 22
H9: 9 | I9: =SUM(B9:H9) -> 9 | J9: LOMO PIMIENTA VERDE | M9: =I9*1 -> 9
I10: =SUM(B10:H10) -> 0 | J10: POLLO PISTACHO | K10: =I9*1 -> 9
H11: 1 | I11: =SUM(B11:H11) -> 1 | J11: RIB EYE | P11: =I11*1 -> 1
I12: =SUM(B12:H12) -> 0 | J12: ARROZ CHAUFA | K12: =I12*1 -> 0
H13: 7 | I13: =SUM(B13:H13) -> 7 | J13: QUESOBURGUESA | L13: =I13*1 -> 7
H14: 6 | I14: =SUM(B14:H14) -> 6 | J14: HAMBURGUESA FULL | L14: =I14*1 -> 6
I15: =SUM(B15:H15) -> 0 | J15: QUESADILLA DE POLLO
I16: =SUM(B16:H16) -> 0 | J16: SURF TACOS CARNE | L16: =I16*1 -> 0
H17: 1 | I17: =SUM(B17:H17) -> 1 | J17: SURF TACOS POLLO
I18: =SUM(B18:H18) -> 0 | J18: CPN BURRITOS POLLO | K18: =I18*1 -> 0
I19: =SUM(B19:H19) -> 0 | J19: CPN BURRTO DE CARNE
I20: =SUM(B20:H20) -> 0 | J20: FILETE DE POLLO | K20: =I20*1 -> 0
I21: =SUM(B21:H21) -> 0 | J21: DEDOS DE POLLO | K21: =I21*1 -> 0
I22: =SUM(B22:H22) -> 0 | J22: LOMITO | M22: =I22*1 -> 0
I23: =SUM(B23:H23) -> 0 | J23: PREMIUM BURGER PATTY 250GR | L23: =I23*1 -> 0
H24: 9 | I24: =SUM(B24:H24) -> 9 | J24: CRISPY SANDWICH | K24: =I24*1 -> 9
H25: 5 | I25: =SUM(B25:H25) -> 5 | J25: ROYAL | O25: =I25*2 -> 10
I26: =SUM(B26:H26) -> 0 | J26: DEDOS DE POLLO CON PAPAS | K26: =I26*1 -> 0
J27: TOTAL | K27: =SUM(K3:K26) -> 36 | L27: =SUM(L3:L26) -> 13 | M27: =SUM(M3:M26) -> 16 | N27: =SUM(N3:N26) -> 22 | O27: =SUM(O3:O26) -> 10 | P27: =SUM(P3:P26) -> 1

Sheet Hoja1
C4: FILET PESCADO
C5: MARLIN
C6: ATUN
C7: CAMARONES
C8: CALAMARES
C9: SALMON TARTAR
C10: CAMARONES JUMBO
C11: CAMARONES JUVENILES
C12: DEDOS PESCADO
C13: CHICHARRON PESCADO
C14: TARTAR
